Traceback (most recent call last):
  File "/Users/uni/Desktop/Lehre/python_class/venv_3_8.nosync/lib/python3.8/site-packages/jupyter_cache/executors/utils.py", line 58, in single_nb_execution
    executenb(
  File "/Users/uni/Desktop/Lehre/python_class/venv_3_8.nosync/lib/python3.8/site-packages/nbclient/client.py", line 1263, in execute
    return NotebookClient(nb=nb, resources=resources, km=km, **kwargs).execute()
  File "/Users/uni/Desktop/Lehre/python_class/venv_3_8.nosync/lib/python3.8/site-packages/nbclient/util.py", line 85, in wrapped
    return just_run(coro(*args, **kwargs))
  File "/Users/uni/Desktop/Lehre/python_class/venv_3_8.nosync/lib/python3.8/site-packages/nbclient/util.py", line 60, in just_run
    return loop.run_until_complete(coro)
  File "/opt/homebrew/Cellar/python@3.8/3.8.15/Frameworks/Python.framework/Versions/3.8/lib/python3.8/asyncio/base_events.py", line 616, in run_until_complete
    return future.result()
  File "/Users/uni/Desktop/Lehre/python_class/venv_3_8.nosync/lib/python3.8/site-packages/nbclient/client.py", line 701, in async_execute
    await self.async_execute_cell(
  File "/Users/uni/Desktop/Lehre/python_class/venv_3_8.nosync/lib/python3.8/site-packages/nbclient/client.py", line 1019, in async_execute_cell
    await self._check_raise_for_error(cell, cell_index, exec_reply)
  File "/Users/uni/Desktop/Lehre/python_class/venv_3_8.nosync/lib/python3.8/site-packages/nbclient/client.py", line 913, in _check_raise_for_error
    raise CellExecutionError.from_cell_and_msg(cell, exec_reply_content)
nbclient.exceptions.CellExecutionError: An error occurred while executing the following cell:
------------------
my_query = 'SELECT * FROM historical_data'

results = conn.execute(my_query)
df = pd.DataFrame(results.fetchall(), columns=results.keys())
df.head(2)
------------------

[0;31m---------------------------------------------------------------------------[0m
[0;31mAttributeError[0m                            Traceback (most recent call last)
File [0;32m~/Desktop/Lehre/python_class/venv_3_8.nosync/lib/python3.8/site-packages/sqlalchemy/engine/base.py:1412[0m, in [0;36mConnection.execute[0;34m(self, statement, parameters, execution_options)[0m
[1;32m   1411[0m [38;5;28;01mtry[39;00m:
[0;32m-> 1412[0m     meth [38;5;241m=[39m [43mstatement[49m[38;5;241;43m.[39;49m[43m_execute_on_connection[49m
[1;32m   1413[0m [38;5;28;01mexcept[39;00m [38;5;167;01mAttributeError[39;00m [38;5;28;01mas[39;00m err:

[0;31mAttributeError[0m: 'str' object has no attribute '_execute_on_connection'

The above exception was the direct cause of the following exception:

[0;31mObjectNotExecutableError[0m                  Traceback (most recent call last)
Cell [0;32mIn [33], line 3[0m
[1;32m      1[0m my_query [38;5;241m=[39m [38;5;124m'[39m[38;5;124mSELECT * FROM historical_data[39m[38;5;124m'[39m
[0;32m----> 3[0m results [38;5;241m=[39m [43mconn[49m[38;5;241;43m.[39;49m[43mexecute[49m[43m([49m[43mmy_query[49m[43m)[49m
[1;32m      4[0m df [38;5;241m=[39m pd[38;5;241m.[39mDataFrame(results[38;5;241m.[39mfetchall(), columns[38;5;241m=[39mresults[38;5;241m.[39mkeys())
[1;32m      5[0m df[38;5;241m.[39mhead([38;5;241m2[39m)

File [0;32m~/Desktop/Lehre/python_class/venv_3_8.nosync/lib/python3.8/site-packages/sqlalchemy/engine/base.py:1414[0m, in [0;36mConnection.execute[0;34m(self, statement, parameters, execution_options)[0m
[1;32m   1412[0m     meth [38;5;241m=[39m statement[38;5;241m.[39m_execute_on_connection
[1;32m   1413[0m [38;5;28;01mexcept[39;00m [38;5;167;01mAttributeError[39;00m [38;5;28;01mas[39;00m err:
[0;32m-> 1414[0m     [38;5;28;01mraise[39;00m exc[38;5;241m.[39mObjectNotExecutableError(statement) [38;5;28;01mfrom[39;00m [38;5;21;01merr[39;00m
[1;32m   1415[0m [38;5;28;01melse[39;00m:
[1;32m   1416[0m     [38;5;28;01mreturn[39;00m meth(
[1;32m   1417[0m         [38;5;28mself[39m,
[1;32m   1418[0m         distilled_parameters,
[1;32m   1419[0m         execution_options [38;5;129;01mor[39;00m NO_OPTIONS,
[1;32m   1420[0m     )

[0;31mObjectNotExecutableError[0m: Not an executable object: 'SELECT * FROM historical_data'
ObjectNotExecutableError: Not an executable object: 'SELECT * FROM historical_data'

