Traceback (most recent call last):
  File "/Users/uni/Desktop/Lehre/python_class/venv.nosync/lib/python3.11/site-packages/nbclient/client.py", line 774, in _async_poll_for_reply
    msg = await ensure_async(self.kc.shell_channel.get_msg(timeout=new_timeout))
          ^^^^^^^^^^^^^^^^^^^^^^^^^^^^^^^^^^^^^^^^^^^^^^^^^^^^^^^^^^^^^^^^^^^^^^
  File "/Users/uni/Desktop/Lehre/python_class/venv.nosync/lib/python3.11/site-packages/nbclient/util.py", line 97, in ensure_async
    result = await obj
             ^^^^^^^^^
  File "/Users/uni/Desktop/Lehre/python_class/venv.nosync/lib/python3.11/site-packages/jupyter_client/channels.py", line 230, in get_msg
    raise Empty
_queue.Empty

During handling of the above exception, another exception occurred:

Traceback (most recent call last):
  File "/Users/uni/Desktop/Lehre/python_class/venv.nosync/lib/python3.11/site-packages/jupyter_cache/executors/utils.py", line 58, in single_nb_execution
    executenb(
  File "/Users/uni/Desktop/Lehre/python_class/venv.nosync/lib/python3.11/site-packages/nbclient/client.py", line 1263, in execute
    return NotebookClient(nb=nb, resources=resources, km=km, **kwargs).execute()
           ^^^^^^^^^^^^^^^^^^^^^^^^^^^^^^^^^^^^^^^^^^^^^^^^^^^^^^^^^^^^^^^^^^^^^
  File "/Users/uni/Desktop/Lehre/python_class/venv.nosync/lib/python3.11/site-packages/nbclient/util.py", line 85, in wrapped
    return just_run(coro(*args, **kwargs))
           ^^^^^^^^^^^^^^^^^^^^^^^^^^^^^^^
  File "/Users/uni/Desktop/Lehre/python_class/venv.nosync/lib/python3.11/site-packages/nbclient/util.py", line 60, in just_run
    return loop.run_until_complete(coro)
           ^^^^^^^^^^^^^^^^^^^^^^^^^^^^^
  File "/opt/homebrew/Cellar/python@3.11/3.11.0/Frameworks/Python.framework/Versions/3.11/lib/python3.11/asyncio/base_events.py", line 650, in run_until_complete
    return future.result()
           ^^^^^^^^^^^^^^^
  File "/opt/homebrew/Cellar/python@3.11/3.11.0/Frameworks/Python.framework/Versions/3.11/lib/python3.11/contextlib.py", line 222, in __aexit__
    await self.gen.athrow(typ, value, traceback)
  File "/Users/uni/Desktop/Lehre/python_class/venv.nosync/lib/python3.11/site-packages/nbclient/client.py", line 646, in async_setup_kernel
    yield
  File "/Users/uni/Desktop/Lehre/python_class/venv.nosync/lib/python3.11/site-packages/nbclient/client.py", line 701, in async_execute
    await self.async_execute_cell(
  File "/Users/uni/Desktop/Lehre/python_class/venv.nosync/lib/python3.11/site-packages/nbclient/client.py", line 1000, in async_execute_cell
    exec_reply = await self.task_poll_for_reply
                 ^^^^^^^^^^^^^^^^^^^^^^^^^^^^^^
  File "/Users/uni/Desktop/Lehre/python_class/venv.nosync/lib/python3.11/site-packages/nbclient/client.py", line 798, in _async_poll_for_reply
    error_on_timeout_execute_reply = await self._async_handle_timeout(timeout, cell)
                                     ^^^^^^^^^^^^^^^^^^^^^^^^^^^^^^^^^^^^^^^^^^^^^^^
  File "/Users/uni/Desktop/Lehre/python_class/venv.nosync/lib/python3.11/site-packages/nbclient/client.py", line 850, in _async_handle_timeout
    raise CellTimeoutError.error_from_timeout_and_cell(
nbclient.exceptions.CellTimeoutError: A cell timed out while it was being executed, after 40 seconds.
The message was: Cell execution timed out.
Here is a preview of the cell contents:
-------------------
['from dash.dependencies import Input, Output', '', 'app = JupyterDash()', '', 'app.layout = html.Div([']
...
['def div_outext(fname, lname):', '    if fname:', '        return fname[::-1], lname[::-1]', '    ', "app.run_server(mode='inline')"]
-------------------

