Traceback (most recent call last):
  File "/Users/uni/Desktop/Lehre/python_class/venv.nosync/lib/python3.11/site-packages/jupyter_cache/executors/utils.py", line 58, in single_nb_execution
    executenb(
  File "/Users/uni/Desktop/Lehre/python_class/venv.nosync/lib/python3.11/site-packages/nbclient/client.py", line 1263, in execute
    return NotebookClient(nb=nb, resources=resources, km=km, **kwargs).execute()
           ^^^^^^^^^^^^^^^^^^^^^^^^^^^^^^^^^^^^^^^^^^^^^^^^^^^^^^^^^^^^^^^^^^^^^
  File "/Users/uni/Desktop/Lehre/python_class/venv.nosync/lib/python3.11/site-packages/nbclient/util.py", line 85, in wrapped
    return just_run(coro(*args, **kwargs))
           ^^^^^^^^^^^^^^^^^^^^^^^^^^^^^^^
  File "/Users/uni/Desktop/Lehre/python_class/venv.nosync/lib/python3.11/site-packages/nbclient/util.py", line 60, in just_run
    return loop.run_until_complete(coro)
           ^^^^^^^^^^^^^^^^^^^^^^^^^^^^^
  File "/opt/homebrew/Cellar/python@3.11/3.11.0/Frameworks/Python.framework/Versions/3.11/lib/python3.11/asyncio/base_events.py", line 650, in run_until_complete
    return future.result()
           ^^^^^^^^^^^^^^^
  File "/opt/homebrew/Cellar/python@3.11/3.11.0/Frameworks/Python.framework/Versions/3.11/lib/python3.11/contextlib.py", line 222, in __aexit__
    await self.gen.athrow(typ, value, traceback)
  File "/Users/uni/Desktop/Lehre/python_class/venv.nosync/lib/python3.11/site-packages/nbclient/client.py", line 646, in async_setup_kernel
    yield
  File "/Users/uni/Desktop/Lehre/python_class/venv.nosync/lib/python3.11/site-packages/nbclient/client.py", line 701, in async_execute
    await self.async_execute_cell(
  File "/Users/uni/Desktop/Lehre/python_class/venv.nosync/lib/python3.11/site-packages/nbclient/client.py", line 1019, in async_execute_cell
    await self._check_raise_for_error(cell, cell_index, exec_reply)
  File "/Users/uni/Desktop/Lehre/python_class/venv.nosync/lib/python3.11/site-packages/nbclient/client.py", line 913, in _check_raise_for_error
    raise CellExecutionError.from_cell_and_msg(cell, exec_reply_content)
nbclient.exceptions.CellExecutionError: An error occurred while executing the following cell:
------------------
pi
------------------

[0;31m---------------------------------------------------------------------------[0m
[0;31mNameError[0m                                 Traceback (most recent call last)
Cell [0;32mIn [24], line 1[0m
[0;32m----> 1[0m [43mpi[49m

[0;31mNameError[0m: name 'pi' is not defined
NameError: name 'pi' is not defined

